[2023-02-24T19:16:02.522+0000] {taskinstance.py:1083} INFO - Dependencies all met for <TaskInstance: nex_Scrapper.export_db manual__2023-02-24T19:13:46.890512+00:00 [queued]>
[2023-02-24T19:16:02.543+0000] {taskinstance.py:1083} INFO - Dependencies all met for <TaskInstance: nex_Scrapper.export_db manual__2023-02-24T19:13:46.890512+00:00 [queued]>
[2023-02-24T19:16:02.543+0000] {taskinstance.py:1279} INFO - 
--------------------------------------------------------------------------------
[2023-02-24T19:16:02.543+0000] {taskinstance.py:1280} INFO - Starting attempt 1 of 1
[2023-02-24T19:16:02.543+0000] {taskinstance.py:1281} INFO - 
--------------------------------------------------------------------------------
[2023-02-24T19:16:02.573+0000] {taskinstance.py:1300} INFO - Executing <Task(PythonOperator): export_db> on 2023-02-24 19:13:46.890512+00:00
[2023-02-24T19:16:02.591+0000] {standard_task_runner.py:55} INFO - Started process 1822 to run task
[2023-02-24T19:16:02.597+0000] {standard_task_runner.py:82} INFO - Running: ['***', 'tasks', 'run', 'nex_Scrapper', 'export_db', 'manual__2023-02-24T19:13:46.890512+00:00', '--job-id', '21', '--raw', '--subdir', 'DAGS_FOLDER/nexrad_scrapper_dag.py', '--cfg-path', '/tmp/tmptunp_ii5']
[2023-02-24T19:16:02.598+0000] {standard_task_runner.py:83} INFO - Job 21: Subtask export_db
[2023-02-24T19:16:02.718+0000] {task_command.py:388} INFO - Running <TaskInstance: nex_Scrapper.export_db manual__2023-02-24T19:13:46.890512+00:00 [running]> on host 41c53da71dc8
[2023-02-24T19:16:02.848+0000] {taskinstance.py:1509} INFO - Exporting the following env vars:
AIRFLOW_CTX_DAG_OWNER=***
AIRFLOW_CTX_DAG_ID=nex_Scrapper
AIRFLOW_CTX_TASK_ID=export_db
AIRFLOW_CTX_EXECUTION_DATE=2023-02-24T19:13:46.890512+00:00
AIRFLOW_CTX_TRY_NUMBER=1
AIRFLOW_CTX_DAG_RUN_ID=manual__2023-02-24T19:13:46.890512+00:00
[2023-02-24T19:16:03.235+0000] {taskinstance.py:1768} ERROR - Task failed with exception
Traceback (most recent call last):
  File "/home/airflow/.local/lib/python3.7/site-packages/airflow/operators/python.py", line 175, in execute
    return_value = self.execute_callable()
  File "/home/airflow/.local/lib/python3.7/site-packages/airflow/operators/python.py", line 192, in execute_callable
    return self.python_callable(*self.op_args, **self.op_kwargs)
  File "/opt/airflow/dags/nexrad_scrapper_dag.py", line 111, in export_db
    s3res.Bucket(os.environ.get('USER_BUCKET_NAME')).upload_file("./dags/scraped_df_nexrad_metadata.db", "database-files/scraped_df_nexrad_metadata.db")
  File "/home/airflow/.local/lib/python3.7/site-packages/boto3/s3/inject.py", line 239, in bucket_upload_file
    Config=Config,
  File "/home/airflow/.local/lib/python3.7/site-packages/boto3/s3/inject.py", line 148, in upload_file
    callback=Callback,
  File "/home/airflow/.local/lib/python3.7/site-packages/boto3/s3/transfer.py", line 292, in upload_file
    future.result()
  File "/home/airflow/.local/lib/python3.7/site-packages/s3transfer/futures.py", line 103, in result
    return self._coordinator.result()
  File "/home/airflow/.local/lib/python3.7/site-packages/s3transfer/futures.py", line 266, in result
    raise self._exception
  File "/home/airflow/.local/lib/python3.7/site-packages/s3transfer/tasks.py", line 269, in _main
    self._submit(transfer_future=transfer_future, **kwargs)
  File "/home/airflow/.local/lib/python3.7/site-packages/s3transfer/upload.py", line 585, in _submit
    upload_input_manager.provide_transfer_size(transfer_future)
  File "/home/airflow/.local/lib/python3.7/site-packages/s3transfer/upload.py", line 244, in provide_transfer_size
    self._osutil.get_file_size(transfer_future.meta.call_args.fileobj)
  File "/home/airflow/.local/lib/python3.7/site-packages/s3transfer/utils.py", line 247, in get_file_size
    return os.path.getsize(filename)
  File "/usr/local/lib/python3.7/genericpath.py", line 50, in getsize
    return os.stat(filename).st_size
FileNotFoundError: [Errno 2] No such file or directory: './dags/scraped_df_nexrad_metadata.db'
[2023-02-24T19:16:03.247+0000] {taskinstance.py:1323} INFO - Marking task as FAILED. dag_id=nex_Scrapper, task_id=export_db, execution_date=20230224T191346, start_date=20230224T191602, end_date=20230224T191603
[2023-02-24T19:16:03.263+0000] {standard_task_runner.py:105} ERROR - Failed to execute job 21 for task export_db ([Errno 2] No such file or directory: './dags/scraped_df_nexrad_metadata.db'; 1822)
[2023-02-24T19:16:03.291+0000] {local_task_job.py:208} INFO - Task exited with return code 1
[2023-02-24T19:16:03.329+0000] {taskinstance.py:2578} INFO - 0 downstream tasks scheduled from follow-on schedule check
